<?xml version="1.0"?>
<robot xmlns:xacro="http://ros.org/wiki/xacro" name="cybergear">
  <xacro:property name="use_gui" value="true"/>

  <!-- Base footprint (usually at z=0) -->
  <link name="base_footprint"/>

  <!-- Main link with STL mesh -->
  <link name="base_link">
    <visual>
      <geometry>
        <mesh filename="package://cybergear_description/meshes/Head.STL" scale="0.001 0.001 0.001"/>
      </geometry>
      <material name="grey">
        <color rgba="0.6 0.6 0.6 1"/>
      </material>
      <origin xyz="-0.00265 -0.136 0.059" rpy="0 1.57079632679 0"/>
    </visual>
  </link>

  <!-- Left shoulder link with STL mesh -->
  <link name="Shoulder_Left_link">
    <visual>
      <geometry>
        <mesh filename="package://cybergear_description/meshes/Shoulder_Left.STL" scale="0.001 0.001 0.001"/>
      </geometry>
      <material name="grey">
        <color rgba="0.6 0.6 0.6 1"/>
      </material>
      <origin xyz="-0.0285 0.065 -0.0177 " rpy="0 0 -1.57079632679"/>
    </visual>
  </link>

  <!-- Right shoulder link with STL mesh -->
  <link name="Shoulder_Right_link">
    <visual>
      <geometry>
        <mesh filename="package://cybergear_description/meshes/Shoulder_Right.STL" scale="0.001 0.001 0.001"/>
      </geometry>
      <material name="grey">
        <color rgba="0.6 0.6 0.6 1"/>
      </material>
      <origin xyz="0.0287 0.06 0.1235" rpy="0 3.141592653589 1.57079632679"/>
    </visual>
  </link>

  <!-- Left Arm link with STL mesh -->
  <link name="Arm_Left_link">
    <visual>
      <geometry>
        <mesh filename="package://cybergear_description/meshes/Arm_Left.STL" scale="0.001 0.001 0.001"/>
      </geometry>
      <material name="grey">
        <color rgba="0.6 0.6 0.6 1"/>
      </material>
      <origin xyz="-0.06465 -0.06405 -0.0775" rpy="0 0 0"/>
    </visual>
  </link>

  <!-- Right Arm link with STL mesh -->
  <link name="Arm_Right_link">
    <visual>
      <geometry>
        <mesh filename="package://cybergear_description/meshes/Arm_Right.STL" scale="0.001 0.001 0.001"/>
      </geometry>
      <material name="grey">
        <color rgba="0.6 0.6 0.6 1"/>
      </material>
      <origin xyz="-0.05234 -0.0517 -0.001" rpy="0 0 0"/>
    </visual>
  </link>

  <!-- Left Body link with STL mesh -->
  <link name="Body_Left_link">
    <visual>
      <geometry>
        <mesh filename="package://cybergear_description/meshes/Body_Left.STL" scale="0.001 0.001 0.001"/>
      </geometry>
      <material name="grey">
        <color rgba="0.6 0.6 0.6 1"/>
      </material>
      <origin xyz="-0.0252 0.0252 -0.0205" rpy="1.57079632679 0 0"/>
    </visual>
  </link>

  <!-- Right Body link with STL mesh -->
  <link name="Body_Right_link">
    <visual>
      <geometry>
        <mesh filename="package://cybergear_description/meshes/Body_Right.STL" scale="0.001 0.001 0.001"/>
      </geometry>
      <material name="grey">
        <color rgba="0.6 0.6 0.6 1"/>
      </material>
      <origin xyz="-0.0252 -0.0252 0.0205" rpy="-1.57079632679 0 0"/>
    </visual>
  </link>

  <!-- Left Leg Mimick link with STL mesh -->
  <link name="Leg_Left_link">
    <visual>
      <geometry>
        <mesh filename="package://cybergear_description/meshes/Leg.STL" scale="0.001 0.001 0.001"/>
      </geometry>
      <material name="grey">
        <color rgba="0.6 0.6 0.6 1"/>
      </material>
      <origin xyz="-0.095 -0.0228 -0.0025" rpy="0 0 0"/>
    </visual>
  </link>

  <!-- Right Leg Mimick link with STL mesh -->
  <link name="Leg_Right_link">
    <visual>
      <geometry>
        <mesh filename="package://cybergear_description/meshes/Leg.STL" scale="0.001 0.001 0.001"/>
      </geometry>
      <material name="grey">
        <color rgba="0.6 0.6 0.6 1"/>
      </material>
      <origin xyz="-0.095 0.0228 0.0025" rpy="3.141592653589 0 0"/>
    </visual>
  </link>

  <!-- Left Wheel with STL mesh -->
  <link name="Left_Wheel">
    <visual>
      <geometry>
        <mesh filename="package://cybergear_description/meshes/Hub_Motor.STL" scale="0.001 0.001 0.001"/>
      </geometry>
      <material name="grey">
        <color rgba="0.6 0.6 0.6 1"/>
      </material>
      <origin xyz="0.1 -0.1 0.075" rpy="0 3.141592653589 0"/>
    </visual>
  </link>

  <!-- Right Wheel with STL mesh -->
  <link name="Right_Wheel">
    <visual>
      <geometry>
        <mesh filename="package://cybergear_description/meshes/Hub_Motor.STL" scale="0.001 0.001 0.001"/>
      </geometry>
      <material name="grey">
        <color rgba="0.6 0.6 0.6 1"/>
      </material>
      <origin xyz="-0.1 -0.1 -0.075" rpy="0 0 0"/>
    </visual>
  </link>

  <!-- Left Coupling link with STL mesh -->
  <link name="Left_Coupling_link">
    <visual>
      <geometry>
        <mesh filename="package://cybergear_description/meshes/Left_Coupling.STL" scale="0.001 0.001 0.001"/>
      </geometry>
      <material name="grey">
        <color rgba="0.6 0.6 0.6 1"/>
      </material>
      <origin xyz="0.2175 0.0175 0" rpy="0 0 3.141592653589"/>
    </visual>
  </link>

  <!-- Right Coupling link with STL mesh -->
  <link name="Right_Coupling_link">
    <visual>
      <geometry>
        <mesh filename="package://cybergear_description/meshes/Right_Coupling.STL" scale="0.001 0.001 0.001"/>
      </geometry>
      <material name="grey">
        <color rgba="0.6 0.6 0.6 1"/>
      </material>
      <origin xyz="0.2175 0.0175 -0.034" rpy="0 0 3.141592653589"/>
    </visual>
  </link>

  

  <!-- Fixed joint from base_footprint to base_link -->
  <joint name="base_joint" type="fixed">
    <parent link="base_footprint"/>
    <child link="base_link"/>
    <origin xyz="0 0 0.35" rpy="0 0 0"/>
  </joint>

  <!-- Revolute joint from base_link to Shoulder_Left_link -->
  <joint name="joint1" type="revolute">
    <parent link="base_link"/>
    <child link="Shoulder_Left_link"/>
    <origin xyz="0.002 -0.075 0" rpy="1.57079632679 0 -1.57079632679"/>
    <axis xyz="0 0 1"/>
    <limit effort="100" velocity="1.0" lower="-1.57079632679" upper="1.57079632679"/>
  </joint>

  <!-- Revolute joint from base_link to Shoulder_Right_link -->
  <joint name="joint2" type="revolute">
    <parent link="base_link"/>
    <child link="Shoulder_Right_link"/>
    <origin xyz="0.002 0.075 0" rpy="1.57079632679 0 -1.57079632679"/>
    <axis xyz="0 0 1"/>
    <limit effort="100" velocity="1.0" lower="-1.57079632679" upper="1.57079632679"/>
  </joint>

  <!-- Revolute joint from Shoulder_Left_link to Arm_Left_link -->
  <joint name="joint3" type="revolute">
    <parent link="Shoulder_Left_link"/>
    <child link="Arm_Left_link"/>
    <origin xyz="0.0445 0 0.0626" rpy="0 1.57079632679 0"/>
    <axis xyz="0 0 1"/>
    <limit effort="100" velocity="1.0" lower="1.775" upper="3.2"/>
  </joint>

  <!-- Revolute joint from Shoulder_Right_link to Arm_Right_link -->
  <joint name="joint4" type="revolute">
    <parent link="Shoulder_Right_link"/>
    <child link="Arm_Right_link"/>
    <origin xyz="-0.0445 0 0.0626" rpy="0 1.57079632679 0"/>
    <axis xyz="0 0 1"/>
    <limit effort="100" velocity="1.0" lower="1.775" upper="3.2"/>
  </joint>

  <!-- Revolute joint from Arm_Left_link to Body_Left_link -->
  <joint name="joint5" type="revolute">
    <parent link="Arm_Left_link"/>
    <child link="Body_Left_link"/>
    <origin xyz="0 0 -0.068" rpy="0 0 0"/>
    <axis xyz="0 0 1"/>
    <limit effort="100" velocity="1.0" lower="0.65" upper="2.5"/>
  </joint>

  <!-- Revolute joint from Arm_Right_link to Body_Right_link -->
  <joint name="joint6" type="revolute">
    <parent link="Arm_Right_link"/>
    <child link="Body_Right_link"/>
    <origin xyz="0 0 0.068" rpy="0 0 0"/>
    <axis xyz="0 0 1"/>
    <limit effort="100" velocity="1.0" lower="0.65" upper="2.5"/>
  </joint>

  <!-- Revolute mimick joint from Body_Left_link to Leg_Left_link -->
  <joint name="joint7" type="continuous">
    <parent link="Body_Left_link"/>
    <child link="Leg_Left_link"/>
    <origin xyz="0.2 0 -0.007" rpy="0 0 3.141592653589"/>
    <axis xyz="0 0 1"/>
    <mimic joint="joint5" multiplier="-1.0" offset="0.0"/>
  </joint>

  <!-- Revolute mimick joint from Body_Right_link to Leg_Right_link -->
  <joint name="joint8" type="continuous">
    <parent link="Body_Right_link"/>
    <child link="Leg_Right_link"/>
    <origin xyz="0.2 0 0.007" rpy="0 0 3.141592653589"/>
    <axis xyz="0 0 1"/>
    <mimic joint="joint6" multiplier="-1.0" offset="0.0"/>
  </joint>

  <!-- Continuous joint from Leg_Left_link to Left_Wheel -->
  <joint name="joint9" type="continuous">
    <parent link="Leg_Left_link"/>
    <child link="Left_Wheel"/>
    <origin xyz="0.16 0 0.0587" rpy="0 0 0"/>
    <axis xyz="0 0 1"/>
  </joint>

  <!-- Continuous joint from Leg_Right_link to Right_Wheel -->
  <joint name="joint10" type="continuous">
    <parent link="Leg_Right_link"/>
    <child link="Right_Wheel"/>
    <origin xyz="0.16 0 -0.0587" rpy="0 0 0"/>
    <axis xyz="0 0 1"/>
  </joint>

  <!-- Revolute mimick joint from Arm_Left_link to Left_Coupling_link -->
  <joint name="joint11" type="continuous">
    <parent link="Leg_Left_link"/>
    <child link="Left_Coupling_link"/>
    <origin xyz="-0.08 0 0.011" rpy="0 0 0"/>
    <axis xyz="0 0 1"/>
    <mimic joint="joint7" multiplier="-1.0" offset="0.0"/>
  </joint>

  <!-- Revolute mimick joint from Arm_Right_link to Right_Coupling_link -->
  <joint name="joint12" type="continuous">
    <parent link="Leg_Right_link"/>
    <child link="Right_Coupling_link"/>
    <origin xyz="-0.08 0 -0.011" rpy="0 0 0"/>
    <axis xyz="0 0 1"/>
    <mimic joint="joint8" multiplier="-1.0" offset="0.0"/>
  </joint>

</robot>
